Workbook

Sheet Raw_Data
A1: PR Final Project – Data Intelligence Dashboard | Raw Transactions Dataset
A2: =CONCATENATE("Report Generated: ",TEXT(NOW(),"DD-MMM-YYYY")) -> Report Generated: 10-May-2026 | E2: =CONCATENATE("Total Records: ",COUNTA(A4:A258)) -> Total Records: 255 | F2: =CONCATENATE("Date Range: ",TEXT(MIN(B4:B258),"DD-MMM-YY")," to ",TEXT(MAX(B4:B258),"DD-MMM-YY")) -> Date Range: 30-Dec-99 to 30-Dec-99
A4: Transaction ID | B4: Order Date | C4: Delivery Date | D4: Customer Name | E4: Customer ID | F4: Gender | G4: Age | H4: City | I4: State | J4: Region | K4: Product Category | L4: Product Name | M4: Quantity | N4: Unit Price | O4: Discount | P4: Revenue | Q4: Profit | R4: Payment Mode | S4: Salesperson
A5: TXN0001 | B5: 2023-12-23 | C5: 2024-01-06 | D5: Meera Chopra | E5: CUST1041 | F5: Male | G5: 65 | H5: Amritsar | I5: Punjab | J5: North | K5: Sports | L5: Running Shoes | M5: 4 | N5: 87.18 | O5: 0 | P5: 348.73 | Q5: 136.71 | R5: Credit Card | S5: Rahul Sharma
A6: TXN0002 | B6: 2023-10-27 | C6: 2023-11-06 | D6: Ananya Verma | E6: CUST1016 | F6: Male | G6: 43 | H6: Chandigarh | I6: Punjab | J6: North | K6: Sports | L6: Yoga Mat | M6: 9 | N6: 26.46 | O6: 0 | P6: 238.15 | Q6: 74.88 | R6: Cash On Delivery | S6: Sneha Singh
A7: TXN0003 | B7: 2023-10-24 | C7: 2023-11-05 | D7: Harsh Malhotra | E7: CUST1034 | F7: Female | G7: 33 | H7: Ranchi | I7: Jharkhand | J7: East | K7: Electronics | L7: Smartphone | M7: 10 | N7: 860.87 | O7: 0 | P7: 8608.73 | Q7: 2223.24 | R7: Net Banking | S7: Amit Kumar
A8: TXN0004 | B8: 2023-12-10 | C8: 2023-12-23 | D8: Arjun Bose | E8: CUST1028 | F8: Male | G8: 52 | H8: Kolkata | I8: West Bengal | J8: East | K8: Home & Kitchen | L8: Table Lamp | M8: 2 | N8: 38.42 | O8: 0.1 | P8: 69.15 | Q8: 26.54 | R8: Cash On Delivery | S8: Vikram Verma
A9: TXN0005 | B9: 2023-03-09 | C9: 2023-03-17 | D9: Kavya Mehta | E9: CUST1071 | F9: Male | G9: 60 | H9: Bhubaneswar | I9: Odisha | J9: East | K9: Electronics | L9: Headphones | M9: 5 | N9: 136.96 | O9: 0.2 | P9: 547.86 | Q9: 122.61 | R9: UPI | S9: Priya Patel
A10: TXN0006 | B10: 2023-03-10 | C10: 2023-03-17 | D10: Vikram Bose | E10: CUST1034 | F10: Male | G10: 61 | H10: Ahmedabad | I10: Gujarat | J10: West | K10: Electronics | L10: Smartphone | M10: 3 | N10: 767.15 | O10: 0.1 | P10: 2071.31 | Q10: 402.94 | R10: Cash On Delivery | S10: Deepa Nair
A11: TXN0007 | B11: 2023-05-09 | C11: 2023-05-12 | D11: Rohan Verma | E11: CUST1057 | F11: Male | G11: 65 | H11: Kochi | I11: Kerala | J11: South | K11: Electronics | L11: Printer | M11: 1 | N11: 340.57 | O11: 0.2 | P11: 272.45 | Q11: 51.09 | R11: Cash On Delivery | S11: Raj Malhotra
A12: TXN0008 | B12: 2023-10-15 | C12: 2023-10-18 | D12: Aditya Reddy | E12: CUST1006 | F12: Female | G12: 26 | H12: Amritsar | I12: Punjab | J12: North | K12: Electronics | L12: Smartphone | M12: 9 | N12: 691.53 | O12: 0 | P12: 6223.76 | Q12: 1414.42 | R12: UPI | S12: Anita Gupta
A13: TXN0009 | B13: 2023-01-21 | C13: 2023-01-29 | D13: Aditya Malhotra | E13: CUST1021 | F13: Male | G13: 33 | H13: Lucknow | I13: Uttar Pradesh | J13: North | K13: Clothing | L13: Jacket | M13: 6 | N13: 104.58 | O13: 0.2 | P13: 502 | Q13: 202.94 | R13: Debit Card | S13: Raj Malhotra
A14: TXN0010 | B14: 2023-01-13 | C14: 2023-01-18 | D14: Meera Bose | E14: CUST1029 | F14: Male | G14: 48 | H14: Ranchi | I14: Jharkhand | J14: East | K14: Beauty | L14: Hair Serum | M14: 4 | N14: 23.92 | O14: 0.2 | P14: 76.54 | Q14: 49.62 | R14: Debit Card | S14: Deepa Nair
A15: TXN0011 | B15: 2023-06-29 | C15: 2023-07-06 | D15: Siddharth Patel | E15: CUST1066 | F15: Female | G15: 59 | H15: Delhi | I15: Delhi | J15: North | K15: Clothing | L15: Jacket | M15: 4 | N15: 90.84 | O15: 0 | P15: 363.38 | Q15: 174.86 | R15: Net Banking | S15: Suresh Reddy
A16: TXN0012 | B16: 2023-06-19 | C16: 2023-06-22 | D16: Raj Rao | E16: CUST1041 | F16: Female | G16: 40 | H16: Bangalore | I16: Karnataka | J16: South | K16: Electronics | L16: Smart Watch | M16: 10 | N16: 308.75 | O16: 0 | P16: 3087.53 | Q16: 553.8 | R16: Net Banking | S16: Kavita Joshi
... A259: TXN0255 | B259: 2023-11-23 | C259: 2023-12-08 | D259: Raj Shah | E259: CUST1013 | F259: Male | G259: 36 | H259: Pune | I259: Maharashtra | J259: West | K259: Books | L259: Biography | M259: 5 | N259: 23.76 | O259: 0.2 | P259: 95.05 | Q259: 55.57 | R259: Net Banking | S259: Amit Kumar

Sheet Analysis
A1: PR Final Project – Analysis Sheet
A3: 📅 DATE & TIME FUNCTIONS
A4: TODAY() | B4: =TODAY() -> 46152 | C4: Current Date
A5: NOW() | B5: =NOW() -> 46152.738 | C5: Current Date & Time
A6: EOMONTH(Today,0) | B6: =EOMONTH(TODAY(),0) -> 46173 | C6: End of Current Month
A7: EOMONTH(Today,-1) | B7: =EOMONTH(TODAY(),-1) -> 46142 | C7: End of Last Month
A8: Days Since First Order | B8: =DATEDIF(DATE(2023,1,1),TODAY(),"D") -> 1225 | C8: Days
A9: Months Covered | B9: =DATEDIF(DATE(2023,1,1),TODAY(),"M") -> 40 | C9: Months
A10: Years Covered | B10: =DATEDIF(DATE(2023,1,1),TODAY(),"Y") -> 3 | C10: Years
A11: Avg Delivery Days (formula) | B11: =IFERROR(AVERAGE(IF(ISNUMBER(DATEVALUE(Raw_Data!C5:C259)-DATEVALUE(Raw_Data!B5:B259)),DATEVALUE(Raw_Data!C5:C259)-DATEVALUE(Raw_Data!B5:B259))),9) -> 3 | C11: Days
A14: 📊 REVENUE SUMMARY BY GROUP
A15: Group By | B15: Category/Value | C15: Revenue (₹) | D15: Orders | E15: Avg Revenue | F15: % Share
A16: Category | B16: Electronics | C16: =SUMIF(Raw_Data!K5:K259,B16,Raw_Data!P5:P259) -> 191975.36 | D16: =COUNTIF(Raw_Data!K5:K259,B16) -> 36 | E16: =IFERROR(C16/D16,0) -> 5332.6489 | F16: =IFERROR(C16/SUM(C16:C21)*100,0) -> 68.644551
A17: Category | B17: Clothing | C17: =SUMIF(Raw_Data!K5:K259,B17,Raw_Data!P5:P259) -> 17399.43 | D17: =COUNTIF(Raw_Data!K5:K259,B17) -> 46 | E17: =IFERROR(C17/D17,0) -> 378.24848 | F17: =IFERROR(C17/SUM(C16:C21)*100,0) -> 6.2215071
A18: Category | B18: Home & Kitchen | C18: =SUMIF(Raw_Data!K5:K259,B18,Raw_Data!P5:P259) -> 45657.2 | D18: =COUNTIF(Raw_Data!K5:K259,B18) -> 41 | E18: =IFERROR(C18/D18,0) -> 1113.5902 | F18: =IFERROR(C18/SUM(C16:C21)*100,0) -> 16.325626
A19: Category | B19: Books | C19: =SUMIF(Raw_Data!K5:K259,B19,Raw_Data!P5:P259) -> 5537.11 | D19: =COUNTIF(Raw_Data!K5:K259,B19) -> 44 | E19: =IFERROR(C19/D19,0) -> 125.84341 | F19: =IFERROR(C19/SUM(C16:C21)*100,0) -> 1.9799022
A20: Category | B20: Sports | C20: =SUMIF(Raw_Data!K5:K259,B20,Raw_Data!P5:P259) -> 13664.27 | D20: =COUNTIF(Raw_Data!K5:K259,B20) -> 46 | E20: =IFERROR(C20/D20,0) -> 297.04935 | F20: =IFERROR(C20/SUM(C16:C21)*100,0) -> 4.8859274
A21: Category | B21: Beauty | C21: =SUMIF(Raw_Data!K5:K259,B21,Raw_Data!P5:P259) -> 5432.47 | D21: =COUNTIF(Raw_Data!K5:K259,B21) -> 42 | E21: =IFERROR(C21/D21,0) -> 129.34452 | F21: =IFERROR(C21/SUM(C16:C21)*100,0) -> 1.9424861
A23: Region | B23: North | C23: =SUMIF(Raw_Data!J5:J259,B23,Raw_Data!P5:P259) -> 73693.55 | D23: =COUNTIF(Raw_Data!J5:J259,B23) -> 56 | E23: =IFERROR(C23/D23,0) -> 1315.9562 | F23: =IFERROR(C23/SUM(C23:C26)*100,0) -> 26.350573
A24: Region | B24: South | C24: =SUMIF(Raw_Data!J5:J259,B24,Raw_Data!P5:P259) -> 77102.86 | D24: =COUNTIF(Raw_Data!J5:J259,B24) -> 65 | E24: =IFERROR(C24/D24,0) -> 1186.1978 | F24: =IFERROR(C24/SUM(C24:C27)*100,0) -> 37.433608
A25: Region | B25: East | C25: =SUMIF(Raw_Data!J5:J259,B25,Raw_Data!P5:P259) -> 78372.68 | D25: =COUNTIF(Raw_Data!J5:J259,B25) -> 74 | E25: =IFERROR(C25/D25,0) -> 1059.0903 | F25: =IFERROR(C25/SUM(C25:C28)*100,0) -> 60.815571
A26: Region | B26: West | C26: =SUMIF(Raw_Data!J5:J259,B26,Raw_Data!P5:P259) -> 50496.75 | D26: =COUNTIF(Raw_Data!J5:J259,B26) -> 60 | E26: =IFERROR(C26/D26,0) -> 841.6125 | F26: =IFERROR(C26/SUM(C26:C29)*100,0) -> 100
A29: 🔡 TEXT FUNCTIONS & ABBREVIATIONS
A30: Customer Name (sample) | B30: =Raw_Data!D5 -> Meera Chopra | C30: Full Name
A31: LEFT - First Name | B31: =LEFT(Raw_Data!D5,FIND(" ",Raw_Data!D5)-1) -> Meera | C31: First Name
A32: RIGHT - Last Name | B32: =RIGHT(Raw_Data!D5,LEN(Raw_Data!D5)-FIND(" ",Raw_Data!D5)) -> Chopra | C32: Last Name
A33: MID - Middle chars | B33: =MID(Raw_Data!D5,3,4) -> era | C33: Chars 3-6
A34: UPPER abbrev | B34: =UPPER(LEFT(Raw_Data!D5,1)&LEFT(RIGHT(Raw_Data!D5,LEN(Raw_Data!D5)-FIND(" ",Raw_Data!D5)),1)) -> MC | C34: Initials
A35: CONCAT ID+Name | B35: =CONCATENATE("Most Frequent Product: ",INDEX(Raw_Data!L5:L259,MATCH(MAX(COUNTIF(Raw_Data!L5:L259,Raw_Data!L5:L259)),COUNTIF(Raw_Data!L5:L259,Raw_Data!L5:L259),0))) -> Most Frequent Product: Yoga Mat | C35: Short Code
A36: TEXT format date | B36: =TEXT(TODAY(),"MMMM DD, YYYY") -> May 10, 2026 | C36: Formatted Date
A37: Category Abbrev | B37: =LEFT(Raw_Data!K5,3)&"-"&Raw_Data!E5 -> Spo-CUST1041 | C37: Cat-ID Code
A40: 🔍 LOOKUP & MATCHING FUNCTIONS
A41: XLOOKUP – TXN0001 Details | B41: =CONCATENATE("Category: ",INDEX(Raw_Data!K5:K259,MATCH(MAX(SUMIF(Raw_Data!K5:K259,Raw_Data!K5:K259,Raw_Data!P5:P259)),SUMIF(Raw_Data!K5:K259,Raw_Data!K5:K259,Raw_Data!P5:P259),0))) -> Category: Sports | C41: Customer Name
A42: XLOOKUP – TXN0001 Revenue | B42: =IFERROR(INDEX(Raw_Data!L5:L259,MATCH(MAX(COUNTIF(Raw_Data!L5:L259,Raw_Data!L5:L259)),COUNTIF(Raw_Data!L5:L259,Raw_Data!L5:L259),0)),"N/A") -> Headphones | C42: Revenue
A43: Most Frequent Product | B43: =INDEX(Raw_Data!L5:L259,MATCH(MAX(COUNTIF(Raw_Data!L5:L259,Raw_Data!L5:L259)),COUNTIF(Raw_Data!L5:L259,Raw_Data!L5:L259),0)) -> Tablet | C43: Top Product
A44: Most Frequent Customer | B44: =INDEX(Raw_Data!D5:D259,MATCH(MAX(COUNTIF(Raw_Data!D5:D259,Raw_Data!D5:D259)),COUNTIF(Raw_Data!D5:D259,Raw_Data!D5:D259),0)) -> Rohan Verma | C44: Top Customer
A45: Count Unique Products | B45: =SUMPRODUCT(1/COUNTIF(Raw_Data!L5:L259,Raw_Data!L5:L259)) -> 48 | C45: Unique Count
A46: Max Revenue City | B46: =INDEX(Raw_Data!H5:H259,MATCH(MAX(Raw_Data!P5:P259),Raw_Data!P5:P259,0)) -> Coimbatore | C46: Best City
A49: 👑 HIGH-VALUE CUSTOMERS (Top 10 by Revenue)
A50: Rank | B50: Customer Name | C50: Total Revenue | D50: Total Orders | E50: Avg Order | F50: Profit | G50: Status
...

Sheet Pivot_Tables
A1: PR Final Project – Pivot Table Analysis (Formula-Based)
A3: 📍 Sales by Region | G3: 🏷️ Sales by Product Category
A4: Region | B4: Total Revenue | C4: Total Profit | D4: Orders | E4: Profit Margin % | G4: Category | H4: Revenue | I4: Profit | J4: Orders | K4: Avg Rev/Order
A5: North | B5: =SUMIF(Raw_Data!J5:J259,A5,Raw_Data!P5:P259) -> 73693.55 | C5: =SUMIF(Raw_Data!J5:J259,A5,Raw_Data!Q5:Q259) -> 19191.1 | D5: =COUNTIF(Raw_Data!J5:J259,A5) -> 56 | E5: =IFERROR(C5/B5,0) -> 0.26041763 | G5: Electronics | H5: =SUMIF(Raw_Data!K5:K259,G5,Raw_Data!P5:P259) -> 191975.36 | I5: =SUMIF(Raw_Data!K5:K259,G5,Raw_Data!Q5:Q259) -> 40044.97 | J5: =COUNTIF(Raw_Data!K5:K259,G5) -> 36 | K5: =IFERROR(H5/J5,0) -> 5332.6489
A6: South | B6: =SUMIF(Raw_Data!J5:J259,A6,Raw_Data!P5:P259) -> 77102.86 | C6: =SUMIF(Raw_Data!J5:J259,A6,Raw_Data!Q5:Q259) -> 19678.02 | D6: =COUNTIF(Raw_Data!J5:J259,A6) -> 65 | E6: =IFERROR(C6/B6,0) -> 0.25521777 | G6: Clothing | H6: =SUMIF(Raw_Data!K5:K259,G6,Raw_Data!P5:P259) -> 17399.43 | I6: =SUMIF(Raw_Data!K5:K259,G6,Raw_Data!Q5:Q259) -> 7304.39 | J6: =COUNTIF(Raw_Data!K5:K259,G6) -> 46 | K6: =IFERROR(H6/J6,0) -> 378.24848
A7: East | B7: =SUMIF(Raw_Data!J5:J259,A7,Raw_Data!P5:P259) -> 78372.68 | C7: =SUMIF(Raw_Data!J5:J259,A7,Raw_Data!Q5:Q259) -> 19127.49 | D7: =COUNTIF(Raw_Data!J5:J259,A7) -> 74 | E7: =IFERROR(C7/B7,0) -> 0.24405813 | G7: Home & Kitchen | H7: =SUMIF(Raw_Data!K5:K259,G7,Raw_Data!P5:P259) -> 45657.2 | I7: =SUMIF(Raw_Data!K5:K259,G7,Raw_Data!Q5:Q259) -> 14162.4 | J7: =COUNTIF(Raw_Data!K5:K259,G7) -> 41 | K7: =IFERROR(H7/J7,0) -> 1113.5902
A8: West | B8: =SUMIF(Raw_Data!J5:J259,A8,Raw_Data!P5:P259) -> 50496.75 | C8: =SUMIF(Raw_Data!J5:J259,A8,Raw_Data!Q5:Q259) -> 14989.5 | D8: =COUNTIF(Raw_Data!J5:J259,A8) -> 60 | E8: =IFERROR(C8/B8,0) -> 0.29684089 | G8: Books | H8: =SUMIF(Raw_Data!K5:K259,G8,Raw_Data!P5:P259) -> 5537.11 | I8: =SUMIF(Raw_Data!K5:K259,G8,Raw_Data!Q5:Q259) -> 3001.52 | J8: =COUNTIF(Raw_Data!K5:K259,G8) -> 44 | K8: =IFERROR(H8/J8,0) -> 125.84341
A9: TOTAL | B9: =SUM(B5:B8) -> 279665.84 | C9: =SUM(C5:C8) -> 72986.11 | D9: =SUM(D5:D8) -> 255 | E9: =IFERROR(C9/B9,0) -> 0.26097613 | G9: Sports | H9: =SUMIF(Raw_Data!K5:K259,G9,Raw_Data!P5:P259) -> 13664.27 | I9: =SUMIF(Raw_Data!K5:K259,G9,Raw_Data!Q5:Q259) -> 5103.56 | J9: =COUNTIF(Raw_Data!K5:K259,G9) -> 46 | K9: =IFERROR(H9/J9,0) -> 297.04935
G10: Beauty | H10: =SUMIF(Raw_Data!K5:K259,G10,Raw_Data!P5:P259) -> 5432.47 | I10: =SUMIF(Raw_Data!K5:K259,G10,Raw_Data!Q5:Q259) -> 3369.27 | J10: =COUNTIF(Raw_Data!K5:K259,G10) -> 42 | K10: =IFERROR(H10/J10,0) -> 129.34452
G11: TOTAL | H11: =SUM(H5:H10) -> 279665.84 | I11: =SUM(I5:I10) -> 72986.11 | J11: =SUM(J5:J10) -> 255 | K11: =IFERROR(H11/J11,0) -> 1096.7288
A13: 📅 Monthly Revenue Trend 2023 | I13: 💳 Payment Mode Analysis
A14: Month | B14: Revenue | C14: Profit | D14: Orders | E14: Growth % | F14: Cum. Revenue | G14: Avg/Order | I14: Payment Mode | J14: Revenue | K14: Orders | L14: Avg Value | M14: % Share
A15: Jan | B15: =SUMPRODUCT((MONTH(DATEVALUE(Raw_Data!B5:B259))=1)*(YEAR(DATEVALUE(Raw_Data!B5:B259))=2023)*Raw_Data!P5:P259) -> 10940.37 | C15: =SUMPRODUCT((MONTH(DATEVALUE(Raw_Data!B5:B259))=1)*(YEAR(DATEVALUE(Raw_Data!B5:B259))=2023)*Raw_Data!Q5:Q259) -> 3156.03 | D15: =SUMPRODUCT((MONTH(DATEVALUE(Raw_Data!B5:B259))=1)*(YEAR(DATEVALUE(Raw_Data!B5:B259))=2023)*1) -> 19 | E15: N/A | F15: =B15 -> 10940.37 | G15: =IFERROR(B15/D15,0) -> 575.80895 | I15: Credit Card | J15: =SUMIF(Raw_Data!R5:R259,I15,Raw_Data!P5:P259) -> 91134.55 | K15: =COUNTIF(Raw_Data!R5:R259,I15) -> 41 | L15: =IFERROR(J15/K15,0) -> 2222.7939 | M15: =IFERROR(J15/SUM(J15:J20)*100,0) -> 32.586944
A16: Feb | B16: =SUMPRODUCT((MONTH(DATEVALUE(Raw_Data!B5:B259))=2)*(YEAR(DATEVALUE(Raw_Data!B5:B259))=2023)*Raw_Data!P5:P259) -> 9383.98 | C16: =SUMPRODUCT((MONTH(DATEVALUE(Raw_Data!B5:B259))=2)*(YEAR(DATEVALUE(Raw_Data!B5:B259))=2023)*Raw_Data!Q5:Q259) -> 3118.33 | D16: =SUMPRODUCT((MONTH(DATEVALUE(Raw_Data!B5:B259))=2)*(YEAR(DATEVALUE(Raw_Data!B5:B259))=2023)*1) -> 18 | E16: =IFERROR((B16-B15)/B15,0) -> -0.14226118 | F16: =F15+B16 -> 20324.35 | G16: =IFERROR(B16/D16,0) -> 521.33222 | I16: Debit Card | J16: =SUMIF(Raw_Data!R5:R259,I16,Raw_Data!P5:P259) -> 19354.49 | K16: =COUNTIF(Raw_Data!R5:R259,I16) -> 47 | L16: =IFERROR(J16/K16,0) -> 411.79766 | M16: =IFERROR(J16/SUM(J15:J20)*100,0) -> 6.9205771
A17: Mar | B17: =SUMPRODUCT((MONTH(DATEVALUE(Raw_Data!B5:B259))=3)*(YEAR(DATEVALUE(Raw_Data!B5:B259))=2023)*Raw_Data!P5:P259) -> 63336.74 | C17: =SUMPRODUCT((MONTH(DATEVALUE(Raw_Data!B5:B259))=3)*(YEAR(DATEVALUE(Raw_Data!B5:B259))=2023)*Raw_Data!Q5:Q259) -> 15371.07 | D17: =SUMPRODUCT((MONTH(DATEVALUE(Raw_Data!B5:B259))=3)*(YEAR(DATEVALUE(Raw_Data!B5:B259))=2023)*1) -> 29 | E17: =IFERROR((B17-B16)/B16,0) -> 5.7494539 | F17: =F16+B17 -> 83661.09 | G17: =IFERROR(B17/D17,0) -> 2184.0255 | I17: UPI | J17: =SUMIF(Raw_Data!R5:R259,I17,Raw_Data!P5:P259) -> 36700.65 | K17: =COUNTIF(Raw_Data!R5:R259,I17) -> 35 | L17: =IFERROR(J17/K17,0) -> 1048.59 | M17: =IFERROR(J17/SUM(J15:J20)*100,0) -> 13.123036
A18: Apr | B18: =SUMPRODUCT((MONTH(DATEVALUE(Raw_Data!B5:B259))=4)*(YEAR(DATEVALUE(Raw_Data!B5:B259))=2023)*Raw_Data!P5:P259) -> 5567.32 | C18: =SUMPRODUCT((MONTH(DATEVALUE(Raw_Data!B5:B259))=4)*(YEAR(DATEVALUE(Raw_Data!B5:B259))=2023)*Raw_Data!Q5:Q259) -> 1739.9 | D18: =SUMPRODUCT((MONTH(DATEVALUE(Raw_Data!B5:B259))=4)*(YEAR(DATEVALUE(Raw_Data!B5:B259))=2023)*1) -> 16 | E18: =IFERROR((B18-B17)/B17,0) -> -0.91209968 | F18: =F17+B18 -> 89228.41 | G18: =IFERROR(B18/D18,0) -> 347.9575 | I18: Net Banking | J18: =SUMIF(Raw_Data!R5:R259,I18,Raw_Data!P5:P259) -> 74030.07 | K18: =COUNTIF(Raw_Data!R5:R259,I18) -> 50 | L18: =IFERROR(J18/K18,0) -> 1480.6014 | M18: =IFERROR(J18/SUM(J15:J20)*100,0) -> 26.470902
A19: May | B19: =SUMPRODUCT((MONTH(DATEVALUE(Raw_Data!B5:B259))=5)*(YEAR(DATEVALUE(Raw_Data!B5:B259))=2023)*Raw_Data!P5:P259) -> 17176.35 | C19: =SUMPRODUCT((MONTH(DATEVALUE(Raw_Data!B5:B259))=5)*(YEAR(DATEVALUE(Raw_Data!B5:B259))=2023)*Raw_Data!Q5:Q259) -> 4479.9 | D19: =SUMPRODUCT((MONTH(DATEVALUE(Raw_Data!B5:B259))=5)*(YEAR(DATEVALUE(Raw_Data!B5:B259))=2023)*1) -> 26 | E19: =IFERROR((B19-B18)/B18,0) -> 2.0852098 | F19: =F18+B19 -> 106404.76 | G19: =IFERROR(B19/D19,0) -> 660.62885 | I19: Cash On Delivery | J19: =SUMIF(Raw_Data!R5:R259,I19,Raw_Data!P5:P259) -> 33547.47 | K19: =COUNTIF(Raw_Data!R5:R259,I19) -> 35 | L19: =IFERROR(J19/K19,0) -> 958.49914 | M19: =IFERROR(J19/SUM(J15:J20)*100,0) -> 11.995555
A20: Jun | B20: =SUMPRODUCT((MONTH(DATEVALUE(Raw_Data!B5:B259))=6)*(YEAR(DATEVALUE(Raw_Data!B5:B259))=2023)*Raw_Data!P5:P259) -> 63994.42 | C20: =SUMPRODUCT((MONTH(DATEVALUE(Raw_Data!B5:B259))=6)*(YEAR(DATEVALUE(Raw_Data!B5:B259))=2023)*Raw_Data!Q5:Q259) -> 14837.55 | D20: =SUMPRODUCT((MONTH(DATEVALUE(Raw_Data!B5:B259))=6)*(YEAR(DATEVALUE(Raw_Data!B5:B259))=2023)*1) -> 27 | E20: =IFERROR((B20-B19)/B19,0) -> 2.7257287 | F20: =F19+B20 -> 170399.18 | G20: =IFERROR(B20/D20,0) -> 2370.1637 | I20: EMI | J20: =SUMIF(Raw_Data!R5:R259,I20,Raw_Data!P5:P259) -> 24898.61 | K20: =COUNTIF(Raw_Data!R5:R259,I20) -> 47 | L20: =IFERROR(J20/K20,0) -> 529.75766 | M20: =IFERROR(J20/SUM(J15:J20)*100,0) -> 8.9029858
A21: Jul | B21: =SUMPRODUCT((MONTH(DATEVALUE(Raw_Data!B5:B259))=7)*(YEAR(DATEVALUE(Raw_Data!B5:B259))=2023)*Raw_Data!P5:P259) -> 7563.77 | C21: =SUMPRODUCT((MONTH(DATEVALUE(Raw_Data!B5:B259))=7)*(YEAR(DATEVALUE(Raw_Data!B5:B259))=2023)*Raw_Data!Q5:Q259) -> 2731.98 | D21: =SUMPRODUCT((MONTH(DATEVALUE(Raw_Data!B5:B259))=7)*(YEAR(DATEVALUE(Raw_Data!B5:B259))=2023)*1) -> 20 | E21: =IFERROR((B21-B20)/B20,0) -> -0.88180579 | F21: =F20+B21 -> 177962.95 | G21: =IFERROR(B21/D21,0) -> 378.1885
A22: Aug | B22: =SUMPRODUCT((MONTH(DATEVALUE(Raw_Data!B5:B259))=8)*(YEAR(DATEVALUE(Raw_Data!B5:B259))=2023)*Raw_Data!P5:P259) -> 12395.72 | C22: =SUMPRODUCT((MONTH(DATEVALUE(Raw_Data!B5:B259))=8)*(YEAR(DATEVALUE(Raw_Data!B5:B259))=2023)*Raw_Data!Q5:Q259) -> 4349.66 | D22: =SUMPRODUCT((MONTH(DATEVALUE(Raw_Data!B5:B259))=8)*(YEAR(DATEVALUE(Raw_Data!B5:B259))=2023)*1) -> 20 | E22: =IFERROR((B22-B21)/B21,0) -> 0.63882826 | F22: =F21+B22 -> 190358.67 | G22: =IFERROR(B22/D22,0) -> 619.786
A23: Sep | B23: =SUMPRODUCT((MONTH(DATEVALUE(Raw_Data!B5:B259))=9)*(YEAR(DATEVALUE(Raw_Data!B5:B259))=2023)*Raw_Data!P5:P259) -> 19717.04 | C23: =SUMPRODUCT((MONTH(DATEVALUE(Raw_Data!B5:B259))=9)*(YEAR(DATEVALUE(Raw_Data!B5:B259))=2023)*Raw_Data!Q5:Q259) -> 5530.43 | D23: =SUMPRODUCT((MONTH(DATEVALUE(Raw_Data!B5:B259))=9)*(YEAR(DATEVALUE(Raw_Data!B5:B259))=2023)*1) -> 21 | E23: =IFERROR((B23-B22)/B22,0) -> 0.5906329 | F23: =F22+B23 -> 210075.71 | G23: =IFERROR(B23/D23,0) -> 938.90667
A24: Oct | B24: =SUMPRODUCT((MONTH(DATEVALUE(Raw_Data!B5:B259))=10)*(YEAR(DATEVALUE(Raw_Data!B5:B259))=2023)*Raw_Data!P5:P259) -> 27399.41 | C24: =SUMPRODUCT((MONTH(DATEVALUE(Raw_Data!B5:B259))=10)*(YEAR(DATEVALUE(Raw_Data!B5:B259))=2023)*Raw_Data!Q5:Q259) -> 7629.3 | D24: =SUMPRODUCT((MONTH(DATEVALUE(Raw_Data!B5:B259))=10)*(YEAR(DATEVALUE(Raw_Data!B5:B259))=2023)*1) -> 22 | E24: =IFERROR((B24-B23)/B23,0) -> 0.389631 | F24: =F23+B24 -> 237475.12 | G24: =IFERROR(B24/D24,0) -> 1245.4277
A25: Nov | B25: =SUMPRODUCT((MONTH(DATEVALUE(Raw_Data!B5:B259))=11)*(YEAR(DATEVALUE(Raw_Data!B5:B259))=2023)*Raw_Data!P5:P259) -> 4411.76 | C25: =SUMPRODUCT((MONTH(DATEVALUE(Raw_Data!B5:B259))=11)*(YEAR(DATEVALUE(Raw_Data!B5:B259))=2023)*Raw_Data!Q5:Q259) -> 1755.55 | D25: =SUMPRODUCT((MONTH(DATEVALUE(Raw_Data!B5:B259))=11)*(YEAR(DATEVALUE(Raw_Data!B5:B259))=2023)*1) -> 14 | E25: =IFERROR((B25-B24)/B24,0) -> -0.83898339 | F25: =F24+B25 -> 241886.88 | G25: =IFERROR(B25/D25,0) -> 315.12571
A26: Dec | B26: =SUMPRODUCT((MONTH(DATEVALUE(Raw_Data!B5:B259))=12)*(YEAR(DATEVALUE(Raw_Data!B5:B259))=2023)*Raw_Data!P5:P259) -> 37778.96 | C26: =SUMPRODUCT((MONTH(DATEVALUE(Raw_Data!B5:B259))=12)*(YEAR(DATEVALUE(Raw_Data!B5:B259))=2023)*Raw_Data!Q5:Q259) -> 8286.41 | D26: =SUMPRODUCT((MONTH(DATEVALUE(Raw_Data!B5:B259))=12)*(YEAR(DATEVALUE(Raw_Data!B5:B259))=2023)*1) -> 23 | E26: =IFERROR((B26-B25)/B25,0) -> 7.5632401 | F26: =F25+B26 -> 279665.84 | G26: =IFERROR(B26/D26,0) -> 1642.5635
A27: TOTAL | B27: =SUM(B15:B26) -> 279665.84 | C27: =SUM(C15:C26) -> 72986.11 | D27: =SUM(D15:D26) -> 255
A29: 👤 Top Customers by Revenue | I29: 🏆 Salesperson Performance
A30: Customer Name | B30: Revenue | C30: Profit | D30: Orders | E30: Avg Order | F30: Margin% | G30: City | I30: Salesperson | J30: Revenue | K30: Orders | L30: Profit | M30: Margin%
A31: Raj Bose | B31: =SUMIF(Raw_Data!D5:D259,A31,Raw_Data!P5:P259) -> 34146.12 | C31: =SUMIF(Raw_Data!D5:D259,A31,Raw_Data!Q5:Q259) -> 7221.65 | D31: =COUNTIF(Raw_Data!D5:D259,A31) -> 2 | E31: =IFERROR(B31/D31,0) -> 17073.06 | F31: =IFERROR(C31/B31,0) -> 0.21149255 | G31: =IFERROR(xlookup(A31,Raw_Data!D5:D259,Raw_Data!H5:H259,"N/A"),"-") -> - | I31: Rahul Sharma | J31: =SUMIF(Raw_Data!S5:S259,I31,Raw_Data!P5:P259) -> 12686.13 | K31: =COUNTIF(Raw_Data!S5:S259,I31) -> 24 | L31: =SUMIF(Raw_Data!S5:S259,I31,Raw_Data!Q5:Q259) -> 4951.69 | M31: =IFERROR(L31/J31,0) -> 0.39032313
A32: Vikram Bose | B32: =SUMIF(Raw_Data!D5:D259,A32,Raw_Data!P5:P259) -> 33639.19 | C32: =SUMIF(Raw_Data!D5:D259,A32,Raw_Data!Q5:Q259) -> 6319.57 | D32: =COUNTIF(Raw_Data!D5:D259,A32) -> 4 | E32: =IFERROR(B32/D32,0) -> 8409.7975 | F32: =IFERROR(C32/B32,0) -> 0.18786332 | G32: =IFERROR(xlookup(A32,Raw_Data!D5:D259,Raw_Data!H5:H259,"N/A"),"-") -> - | I32: Priya Patel | J32: =SUMIF(Raw_Data!S5:S259,I32,Raw_Data!P5:P259) -> 13616.9 | K32: =COUNTIF(Raw_Data!S5:S259,I32) -> 24 | L32: =SUMIF(Raw_Data!S5:S259,I32,Raw_Data!Q5:Q259) -> 4041.59 | M32: =IFERROR(L32/J32,0) -> 0.29680691
A33: Divya Rao | B33: =SUMIF(Raw_Data!D5:D259,A33,Raw_Data!P5:P259) -> 20521.9 | C33: =SUMIF(Raw_Data!D5:D259,A33,Raw_Data!Q5:Q259) -> 4538.4 | D33: =COUNTIF(Raw_Data!D5:D259,A33) -> 2 | E33: =IFERROR(B33/D33,0) -> 10260.95 | F33: =IFERROR(C33/B33,0) -> 0.22114911 | G33: =IFERROR(xlookup(A33,Raw_Data!D5:D259,Raw_Data!H5:H259,"N/A"),"-") -> - | I33: Amit Kumar | J33: =SUMIF(Raw_Data!S5:S259,I33,Raw_Data!P5:P259) -> 22262.72 | K33: =COUNTIF(Raw_Data!S5:S259,I33) -> 30 | L33: =SUMIF(Raw_Data!S5:S259,I33,Raw_Data!Q5:Q259) -> 7219.82 | M33: =IFERROR(L33/J33,0) -> 0.32430089
A34: Divya Shah | B34: =SUMIF(Raw_Data!D5:D259,A34,Raw_Data!P5:P259) -> 19850.92 | C34: =SUMIF(Raw_Data!D5:D259,A34,Raw_Data!Q5:Q259) -> 4120.65 | D34: =COUNTIF(Raw_Data!D5:D259,A34) -> 4 | E34: =IFERROR(B34/D34,0) -> 4962.73 | F34: =IFERROR(C34/B34,0) -> 0.2075798 | G34: =IFERROR(xlookup(A34,Raw_Data!D5:D259,Raw_Data!H5:H259,"N/A"),"-") -> - | I34: Sneha Singh | J34: =SUMIF(Raw_Data!S5:S259,I34,Raw_Data!P5:P259) -> 14072.4 | K34: =COUNTIF(Raw_Data!S5:S259,I34) -> 30 | L34: =SUMIF(Raw_Data!S5:S259,I34,Raw_Data!Q5:Q259) -> 4375.71 | M34: =IFERROR(L34/J34,0) -> 0.3109427
A35: Aarav Patel | B35: =SUMIF(Raw_Data!D5:D259,A35,Raw_Data!P5:P259) -> 17080.75 | C35: =SUMIF(Raw_Data!D5:D259,A35,Raw_Data!Q5:Q259) -> 3705.59 | D35: =COUNTIF(Raw_Data!D5:D259,A35) -> 3 | E35: =IFERROR(B35/D35,0) -> 5693.5833 | F35: =IFERROR(C35/B35,0) -> 0.21694539 | G35: =IFERROR(xlookup(A35,Raw_Data!D5:D259,Raw_Data!H5:H259,"N/A"),"-") -> - | I35: Vikram Verma | J35: =SUMIF(Raw_Data!S5:S259,I35,Raw_Data!P5:P259) -> 63982.33 | K35: =COUNTIF(Raw_Data!S5:S259,I35) -> 22 | L35: =SUMIF(Raw_Data!S5:S259,I35,Raw_Data!Q5:Q259) -> 14111.03 | M35: =IFERROR(L35/J35,0) -> 0.22054574
A36: Harsh Malhotra | B36: =SUMIF(Raw_Data!D5:D259,A36,Raw_Data!P5:P259) -> 9596.44 | C36: =SUMIF(Raw_Data!D5:D259,A36,Raw_Data!Q5:Q259) -> 2676.7 | D36: =COUNTIF(Raw_Data!D5:D259,A36) -> 4 | E36: =IFERROR(B36/D36,0) -> 2399.11 | F36: =IFERROR(C36/B36,0) -> 0.27892635 | G36: =IFERROR(xlookup(A36,Raw_Data!D5:D259,Raw_Data!H5:H259,"N/A"),"-") -> - | I36: Anita Gupta | J36: =SUMIF(Raw_Data!S5:S259,I36,Raw_Data!P5:P259) -> 37475.47 | K36: =COUNTIF(Raw_Data!S5:S259,I36) -> 24 | L36: =SUMIF(Raw_Data!S5:S259,I36,Raw_Data!Q5:Q259) -> 9366.91 | M36: =IFERROR(L36/J36,0) -> 0.24994777
A37: Arjun Mehta | B37: =SUMIF(Raw_Data!D5:D259,A37,Raw_Data!P5:P259) -> 8218.25 | C37: =SUMIF(Raw_Data!D5:D259,A37,Raw_Data!Q5:Q259) -> 1847.79 | D37: =COUNTIF(Raw_Data!D5:D259,A37) -> 4 | E37: =IFERROR(B37/D37,0) -> 2054.5625 | F37: =IFERROR(C37/B37,0) -> 0.22483984 | G37: =IFERROR(xlookup(A37,Raw_Data!D5:D259,Raw_Data!H5:H259,"N/A"),"-") -> - | I37: Raj Malhotra | J37: =SUMIF(Raw_Data!S5:S259,I37,Raw_Data!P5:P259) -> 45176.21 | K37: =COUNTIF(Raw_Data!S5:S259,I37) -> 26 | L37: =SUMIF(Raw_Data!S5:S259,I37,Raw_Data!Q5:Q259) -> 10078.76 | M37: =IFERROR(L37/J37,0) -> 0.22309884
A38: Aditya Reddy | B38: =SUMIF(Raw_Data!D5:D259,A38,Raw_Data!P5:P259) -> 6909.39 | C38: =SUMIF(Raw_Data!D5:D259,A38,Raw_Data!Q5:Q259) -> 1668.51 | D38: =COUNTIF(Raw_Data!D5:D259,A38) -> 5 | E38: =IFERROR(B38/D38,0) -> 1381.878 | F38: =IFERROR(C38/B38,0) -> 0.24148441 | G38: =IFERROR(xlookup(A38,Raw_Data!D5:D259,Raw_Data!H5:H259,"N/A"),"-") -> - | I38: Deepa Nair | J38: =SUMIF(Raw_Data!S5:S259,I38,Raw_Data!P5:P259) -> 25374.3 | K38: =COUNTIF(Raw_Data!S5:S259,I38) -> 27 | L38: =SUMIF(Raw_Data!S5:S259,I38,Raw_Data!Q5:Q259) -> 6701.24 | M38: =IFERROR(L38/J38,0) -> 0.26409556
A39: Nisha Rao | B39: =SUMIF(Raw_Data!D5:D259,A39,Raw_Data!P5:P259) -> 6905.81 | C39: =SUMIF(Raw_Data!D5:D259,A39,Raw_Data!Q5:Q259) -> 1860.39 | D39: =COUNTIF(Raw_Data!D5:D259,A39) -> 8 | E39: =IFERROR(B39/D39,0) -> 863.22625 | F39: =IFERROR(C39/B39,0) -> 0.2693949 | G39: =IFERROR(xlookup(A39,Raw_Data!D5:D259,Raw_Data!H5:H259,"N/A"),"-") -> -
A40: Kavya Kumar | B40: =SUMIF(Raw_Data!D5:D259,A40,Raw_Data!P5:P259) -> 5556.48 | C40: =SUMIF(Raw_Data!D5:D259,A40,Raw_Data!Q5:Q259) -> 2097.05 | D40: =COUNTIF(Raw_Data!D5:D259,A40) -> 5 | E40: =IFERROR(B40/D40,0) -> 1111.296 | F40: =IFERROR(C40/B40,0) -> 0.3774062 | G40: =IFERROR(xlookup(A40,Raw_Data!D5:D259,Raw_Data!H5:H259,"N/A"),"-") -> -

Sheet Charts
A1: PR Final Project – Charts & Visualizations
A3: Revenue by Region | E3: Monthly Revenue Trend | I3: Revenue by Category | L3: Revenue by Payment Mode
A4: Region | B4: Revenue | C4: Profit | E4: Month | F4: Revenue | G4: Profit | I4: Category | J4: Revenue | L4: Payment Mode | M4: Revenue
A5: East | B5: 78372.68 | C5: 19127.49 | E5: Jan | F5: 10940.37 | G5: 3156.03 | I5: Beauty | J5: 5432.47 | L5: Cash On Delivery | M5: 33547.47
A6: North | B6: 73693.55 | C6: 19191.1 | E6: Feb | F6: 9383.98 | G6: 3118.33 | I6: Books | J6: 5537.11 | L6: Credit Card | M6: 91134.55
A7: South | B7: 77102.86 | C7: 19678.02 | E7: Mar | F7: 63336.74 | G7: 15371.07 | I7: Clothing | J7: 17399.43 | L7: Debit Card | M7: 19354.49
A8: West | B8: 50496.75 | C8: 14989.5 | E8: Apr | F8: 5567.32 | G8: 1739.9 | I8: Electronics | J8: 191975.36 | L8: EMI | M8: 24898.61
E9: May | F9: 17176.35 | G9: 4479.9 | I9: Home & Kitchen | J9: 45657.2 | L9: Net Banking | M9: 74030.07
E10: Jun | F10: 63994.42 | G10: 14837.55 | I10: Sports | J10: 13664.27 | L10: UPI | M10: 36700.65
E11: Jul | F11: 7563.77 | G11: 2731.98
E12: Aug | F12: 12395.72 | G12: 4349.66
E13: Sep | F13: 19717.04 | G13: 5530.43
E14: Oct | F14: 27399.41 | G14: 7629.3
E15: Nov | F15: 4411.76 | G15: 1755.55
E16: Dec | F16: 37778.96 | G16: 8286.41

Sheet Dashboard
A2: 📊 PR FINAL PROJECT – DATA INTELLIGENCE DASHBOARD
A4: 💰 Total Revenue | D4: 📈 Total Profit | G4: 🛒 Total Orders | J4: 🏆 Top Region | M4: ⭐ Top Category | P4: 💡 Avg Order Val | S4: 📊 Profit Margin
A5: =SUM(Raw_Data!P5:P259) -> 279665.84 | D5: =SUM(Raw_Data!Q5:Q259) -> 72986.11 | G5: =COUNTA(Raw_Data!A5:A259) -> 255 | J5: =INDEX({"North","South","East","West"},MATCH(MAX(SUMIF(Raw_Data!J5:J259,{"North","South","East","West"},Raw_Data!P5:P259)),SUMIF(Raw_Data!J5:J259,{"North","South","East","West"},Raw_Data!P5:P259),0)) -> East | M5: =INDEX(Raw_Data!K5:K259,MATCH(MAX(SUMIF(Raw_Data!K5:K259,Raw_Data!K5:K259,Raw_Data!P5:P259)),SUMIF(Raw_Data!K5:K259,Raw_Data!K5:K259,Raw_Data!P5:P259),0)) -> Sports | P5: =IFERROR(SUM(Raw_Data!P5:P259)/COUNTA(Raw_Data!A5:A259),0) -> 1096.7288 | S5: =IFERROR(SUM(Raw_Data!Q5:Q259)/SUM(Raw_Data!P5:P259),0) -> 0.26097613
A7: ↑ All Time | D7: ↑ Growing | G7: Transactions | J7: Best Performer | M7: Highest Revenue | P7: Per Transaction | S7: Overall %
A9: 📍 Revenue by Region | G9: 🏷️ Revenue by Category | M9: 👑 Top 5 Customers
A10: Region | B10: Revenue (₹) | C10: Profit (₹) | D10: Orders | E10: Margin | G10: Category | H10: Revenue | I10: Profit | J10: Orders | K10: Trend | M10: Customer Name | N10: Revenue | O10: Orders | P10: Status | Q10: City
A11: North | B11: =SUMIF(Raw_Data!J5:J259,A11,Raw_Data!P5:P259) -> 73693.55 | C11: =SUMIF(Raw_Data!J5:J259,A11,Raw_Data!Q5:Q259) -> 19191.1 | D11: =COUNTIF(Raw_Data!J5:J259,A11) -> 56 | E11: =IFERROR(C11/B11,0) -> 0.26041763 | G11: Electronics | H11: =SUMIF(Raw_Data!K5:K259,G11,Raw_Data!P5:P259) -> 191975.36 | I11: =SUMIF(Raw_Data!K5:K259,G11,Raw_Data!Q5:Q259) -> 40044.97 | J11: =COUNTIF(Raw_Data!K5:K259,G11) -> 36 | K11: =IF(H11>AVERAGE(H11:H15),"▲ Above Avg","▼ Below Avg") -> ▲ Above Avg | M11: Raj Bose | N11: =SUMIF(Raw_Data!D5:D259,M11,Raw_Data!P5:P259) -> 34146.12 | O11: =COUNTIF(Raw_Data!D5:D259,M11) -> 2 | P11: =IF(N11>3000,"⭐ VIP","Premium") -> ⭐ VIP | Q11: =IFERROR(xlookup(M11,Raw_Data!D5:D259,Raw_Data!H5:H259,"-"),"-") -> -
A12: South | B12: =SUMIF(Raw_Data!J5:J259,A12,Raw_Data!P5:P259) -> 77102.86 | C12: =SUMIF(Raw_Data!J5:J259,A12,Raw_Data!Q5:Q259) -> 19678.02 | D12: =COUNTIF(Raw_Data!J5:J259,A12) -> 65 | E12: =IFERROR(C12/B12,0) -> 0.25521777 | G12: Clothing | H12: =SUMIF(Raw_Data!K5:K259,G12,Raw_Data!P5:P259) -> 17399.43 | I12: =SUMIF(Raw_Data!K5:K259,G12,Raw_Data!Q5:Q259) -> 7304.39 | J12: =COUNTIF(Raw_Data!K5:K259,G12) -> 46 | K12: =IF(H12>AVERAGE(H11:H15),"▲ Above Avg","▼ Below Avg") -> ▼ Below Avg | M12: Vikram Bose | N12: =SUMIF(Raw_Data!D5:D259,M12,Raw_Data!P5:P259) -> 33639.19 | O12: =COUNTIF(Raw_Data!D5:D259,M12) -> 4 | P12: =IF(N12>3000,"⭐ VIP","Premium") -> ⭐ VIP | Q12: =IFERROR(xlookup(M12,Raw_Data!D5:D259,Raw_Data!H5:H259,"-"),"-") -> -
A13: East | B13: =SUMIF(Raw_Data!J5:J259,A13,Raw_Data!P5:P259) -> 78372.68 | C13: =SUMIF(Raw_Data!J5:J259,A13,Raw_Data!Q5:Q259) -> 19127.49 | D13: =COUNTIF(Raw_Data!J5:J259,A13) -> 74 | E13: =IFERROR(C13/B13,0) -> 0.24405813 | G13: Home & Kitchen | H13: =SUMIF(Raw_Data!K5:K259,G13,Raw_Data!P5:P259) -> 45657.2 | I13: =SUMIF(Raw_Data!K5:K259,G13,Raw_Data!Q5:Q259) -> 14162.4 | J13: =COUNTIF(Raw_Data!K5:K259,G13) -> 41 | K13: =IF(H13>AVERAGE(H11:H15),"▲ Above Avg","▼ Below Avg") -> ▼ Below Avg | M13: Divya Rao | N13: =SUMIF(Raw_Data!D5:D259,M13,Raw_Data!P5:P259) -> 20521.9 | O13: =COUNTIF(Raw_Data!D5:D259,M13) -> 2 | P13: =IF(N13>3000,"⭐ VIP","Premium") -> ⭐ VIP | Q13: =IFERROR(xlookup(M13,Raw_Data!D5:D259,Raw_Data!H5:H259,"-"),"-") -> -
A14: West | B14: =SUMIF(Raw_Data!J5:J259,A14,Raw_Data!P5:P259) -> 50496.75 | C14: =SUMIF(Raw_Data!J5:J259,A14,Raw_Data!Q5:Q259) -> 14989.5 | D14: =COUNTIF(Raw_Data!J5:J259,A14) -> 60 | E14: =IFERROR(C14/B14,0) -> 0.29684089 | G14: Books | H14: =SUMIF(Raw_Data!K5:K259,G14,Raw_Data!P5:P259) -> 5537.11 | I14: =SUMIF(Raw_Data!K5:K259,G14,Raw_Data!Q5:Q259) -> 3001.52 | J14: =COUNTIF(Raw_Data!K5:K259,G14) -> 44 | K14: =IF(H14>AVERAGE(H11:H15),"▲ Above Avg","▼ Below Avg") -> ▼ Below Avg | M14: Divya Shah | N14: =SUMIF(Raw_Data!D5:D259,M14,Raw_Data!P5:P259) -> 19850.92 | O14: =COUNTIF(Raw_Data!D5:D259,M14) -> 4 | P14: =IF(N14>3000,"⭐ VIP","Premium") -> ⭐ VIP | Q14: =IFERROR(xlookup(M14,Raw_Data!D5:D259,Raw_Data!H5:H259,"-"),"-") -> -
G15: Sports | H15: =SUMIF(Raw_Data!K5:K259,G15,Raw_Data!P5:P259) -> 13664.27 | I15: =SUMIF(Raw_Data!K5:K259,G15,Raw_Data!Q5:Q259) -> 5103.56 | J15: =COUNTIF(Raw_Data!K5:K259,G15) -> 46 | K15: =IF(H15>AVERAGE(H11:H15),"▲ Above Avg","▼ Below Avg") -> ▼ Below Avg | M15: Aarav Patel | N15: =SUMIF(Raw_Data!D5:D259,M15,Raw_Data!P5:P259) -> 17080.75 | O15: =COUNTIF(Raw_Data!D5:D259,M15) -> 3 | P15: =IF(N15>3000,"⭐ VIP","Premium") -> ⭐ VIP | Q15: =IFERROR(xlookup(M15,Raw_Data!D5:D259,Raw_Data!H5:H259,"-"),"-") -> -
A22: 🎯 KPI Performance Indicators
A23: KPI Name | C23: Actual | D23: Target | E23: Status | F23: Icon
A24: Revenue vs Target | C24: =SUM(Raw_Data!P5:P259) -> 279665.84 | D24: 500000 | E24: =IF(C24>=D24,"✅ Met","❌ Below") -> ❌ Below | F24: =IF(C24>=D24,"▲ Above Target","▼ Below Target") -> ▼ Below Target
A25: Profit Margin | C25: =IFERROR(SUM(Raw_Data!Q5:Q259)/SUM(Raw_Data!P5:P259),0) -> 0.26097613 | D25: 0.35 | E25: =IF(C25>=D25,"✅ Met","❌ Below") -> ❌ Below | F25: =IF(C25>=D25,"▲ Above Target","▼ Below Target") -> ▼ Below Target
A26: Orders Completion | C26: =COUNTA(Raw_Data!A5:A259) -> 255 | D26: 200 | E26: =IF(C26>=D26,"✅ Met","❌ Below") -> ❌ Below | F26: =IF(C26>=D26,"▲ Above Target","▼ Below Target") -> ▼ Below Target
A27: Avg Order Value | C27: =IFERROR(SUM(Raw_Data!P5:P259)/COUNTA(Raw_Data!A5:A259),0) -> 1096.7288 | D27: 300 | E27: =IF(C27>=D27,"✅ Met","❌ Below") -> ❌ Below | F27: =IF(C27>=D27,"▲ Above Target","▼ Below Target") -> ▼ Below Target
A28: Discount Rate | C28: =AVERAGE(Raw_Data!O5:O259) -> 0.068627451 | D28: 0.1 | E28: =IF(C28>=D28,"✅ Met","❌ Below") -> ❌ Below | F28: =IF(C28>=D28,"▲ Above Target","▼ Below Target") -> ▼ Below Target

Sheet Insights_Report
A1: PR Final Project – Business Insights & Storytelling Report
A2: =CONCATENATE("Report Date: ",TEXT(TODAY(),"DD MMMM YYYY")," | Data Intelligence Dashboard Final Analysis") -> Report Date: 10 May 2026 | Data Intelligence Dashboard Final Analysis
A4: 📋 1. EXECUTIVE SUMMARY
A5: Total Revenue Generated (₹) | D5: =SUM(Raw_Data!P5:P259) -> 279665.84 | E5: Sum of all transaction revenues across 2023
A6: Total Profit Earned (₹) | D6: =SUM(Raw_Data!Q5:Q259) -> 72986.11 | E6: Net profit after cost deduction
A7: Overall Profit Margin | D7: =IFERROR(SUM(Raw_Data!Q5:Q259)/SUM(Raw_Data!P5:P259),0) -> 0.26097613 | E7: Profit as % of total revenue
A8: Total Transactions | D8: =COUNTA(Raw_Data!A5:A259) -> 255 | E8: Number of unique sales orders processed
A9: Unique Customers | D9: =SUMPRODUCT(1/COUNTIF(Raw_Data!D5:D259,Raw_Data!D5:D259)) -> 75 | E9: Distinct customer count based on name match
A10: Average Order Value (₹) | D10: =IFERROR(SUM(Raw_Data!P5:P259)/COUNTA(Raw_Data!A5:A259),0) -> 1096.7288 | E10: Revenue per transaction on average
A11: Average Discount Applied | D11: =AVERAGE(Raw_Data!O5:O259) -> 0.068627451 | E11: Mean discount % across all orders
A12: Average Delivery Days | D12: =AVERAGE(IFERROR(DATEVALUE(Raw_Data!C5:C259)-DATEVALUE(Raw_Data!B5:B259),0)) -> 3 | E12: Average days from order to delivery
A14: 🏷️ 2. PRODUCT & CATEGORY PERFORMANCE
A15: Highest Revenue Category | D15: =INDEX({"Electronics","Clothing","Home & Kitchen","Books","Sports","Beauty"},MATCH(MAX(SUMIF(Raw_Data!K5:K259,{"Electronics","Clothing","Home & Kitchen","Books","Sports","Beauty"},Raw_Data!P5:P259)),SUMIF(Raw_Data!K5:K259,{"Electronics","Clothing","Home & Kitchen","Books","Sports","Beauty"},Raw_Data!P5:P259),0)) -> Electronics | E15: Category contributing maximum revenue
A16: Lowest Revenue Category | D16: =INDEX({"Electronics","Clothing","Home & Kitchen","Books","Sports","Beauty"},MATCH(MIN(SUMIF(Raw_Data!K5:K259,{"Electronics","Clothing","Home & Kitchen","Books","Sports","Beauty"},Raw_Data!P5:P259)),SUMIF(Raw_Data!K5:K259,{"Electronics","Clothing","Home & Kitchen","Books","Sports","Beauty"},Raw_Data!P5:P259),0)) -> Beauty | E16: Category with lowest total revenue contribution
A17: Most Purchased Product | D17: =INDEX(Raw_Data!L5:L259,MATCH(MAX(COUNTIF(Raw_Data!L5:L259,Raw_Data!L5:L259)),COUNTIF(Raw_Data!L5:L259,Raw_Data!L5:L259),0)) -> Headphones | E17: Product appearing most frequently in orders
A18: Electronics Revenue | D18: =SUMIF(Raw_Data!K5:K259,"Electronics",Raw_Data!P5:P259) -> 191975.36 | E18: Total revenue from Electronics category
A19: Beauty Profit Margin | D19: =IFERROR(SUMIF(Raw_Data!K5:K259,"Beauty",Raw_Data!Q5:Q259)/SUMIF(Raw_Data!K5:K259,"Beauty",Raw_Data!P5:P259),0) -> 0.62020959 | E19: Beauty has highest margins – strong profitability driver
A20: Books Avg Order Size | D20: =IFERROR(SUMIF(Raw_Data!K5:K259,"Books",Raw_Data!P5:P259)/COUNTIF(Raw_Data!K5:K259,"Books"),0) -> 125.84341 | E20: Lower value but high frequency
A22: 📍 3. REGIONAL PERFORMANCE ANALYSIS
A23: North Region Revenue | D23: =SUMIF(Raw_Data!J5:J259,"North",Raw_Data!P5:P259) -> 73693.55 | E23: Total revenue contributed by North region customers
A24: South Region Revenue | D24: =SUMIF(Raw_Data!J5:J259,"South",Raw_Data!P5:P259) -> 77102.86 | E24: Total revenue contributed by South region customers
A25: East Region Revenue | D25: =SUMIF(Raw_Data!J5:J259,"East",Raw_Data!P5:P259) -> 78372.68 | E25: Total revenue contributed by East region customers
A26: West Region Revenue | D26: =SUMIF(Raw_Data!J5:J259,"West",Raw_Data!P5:P259) -> 50496.75 | E26: Total revenue contributed by West region customers
A27: Best Performing Region | D27: =INDEX({"North","South","East","West"},MATCH(MAX(SUMIF(Raw_Data!J5:J259,{"North","South","East","West"},Raw_Data!P5:P259)),SUMIF(Raw_Data!J5:J259,{"North","South","East","West"},Raw_Data!P5:P259),0)) -> East | E27: Region with highest cumulative revenue
A28: Weakest Region | D28: =INDEX({"North","South","East","West"},MATCH(MIN(SUMIF(Raw_Data!J5:J259,{"North","South","East","West"},Raw_Data!P5:P259)),SUMIF(Raw_Data!J5:J259,{"North","South","East","West"},Raw_Data!P5:P259),0)) -> West | E28: Region needing improvement and focus
A29: Regional Revenue Variance (₹) | D29: =MAX(SUMIF(Raw_Data!J5:J259,{"North","South","East","West"},Raw_Data!P5:P259))-MIN(SUMIF(Raw_Data!J5:J259,{"North","South","East","West"},Raw_Data!P5:P259)) -> 27875.93 | E29: Gap between best and worst region – signals inequality
A31: 👤 4. CUSTOMER BEHAVIOR ANALYSIS
A32: Top Customer (By Revenue) | D32: =INDEX(Raw_Data!D5:D259,MATCH(MAX(SUMIF(Raw_Data!D5:D259,Raw_Data!D5:D259,Raw_Data!P5:P259)),SUMIF(Raw_Data!D5:D259,Raw_Data!D5:D259,Raw_Data!P5:P259),0)) -> Vikram Bose | E32: Single highest revenue-generating customer
A33: Most Frequent Customer | D33: =INDEX(Raw_Data!D5:D259,MATCH(MAX(COUNTIF(Raw_Data!D5:D259,Raw_Data!D5:D259)),COUNTIF(Raw_Data!D5:D259,Raw_Data!D5:D259),0)) -> Ananya Verma | E33: Customer with highest order frequency – loyal buyer
A34: Male Customer Revenue | D34: =SUMIF(Raw_Data!F5:F259,"Male",Raw_Data!P5:P259) -> 181892.24 | E34: Revenue from male customers
A35: Female Customer Revenue | D35: =SUMIF(Raw_Data!F5:F259,"Female",Raw_Data!P5:P259) -> 97773.6 | E35: Revenue from female customers
A36: Top Payment Mode | D36: =INDEX(Raw_Data!R5:R259,MATCH(MAX(COUNTIF(Raw_Data!R5:R259,Raw_Data!R5:R259)),COUNTIF(Raw_Data!R5:R259,Raw_Data!R5:R259),0)) -> Cash On Delivery | E36: Most preferred payment method by customers
A37: High Discount Orders (>15%) | D37: =COUNTIF(Raw_Data!O5:O259,">0.15") -> 33 | E37: Orders with aggressive discounting – margin erosion risk
A39: 💰 5. PROFITABILITY INSIGHTS
A40: Total Profit (₹) | D40: =SUM(Raw_Data!Q5:Q259) -> 72986.11 | E40: Gross profit across all transactions
A41: Highest Profit Transaction | D41: =MAX(Raw_Data!Q5:Q259) -> 7186.93 | E41: Single transaction with maximum profit
A42: Lowest Profit Transaction | D42: =MIN(Raw_Data!Q5:Q259) -> 3.75 | E42: Lowest profit – review for pricing issues
A43: Avg Profit per Order | D43: =IFERROR(SUM(Raw_Data!Q5:Q259)/COUNTA(Raw_Data!A5:A259),0) -> 286.22004 | E43: Mean profit generated per transaction
A44: Revenue without Discounts | D44: =SUMPRODUCT(Raw_Data!N5:N259*Raw_Data!M5:M259) -> 292830.88 | E44: Hypothetical revenue if no discounts were applied
A45: Revenue Lost to Discounts | D45: =SUMPRODUCT(Raw_Data!N5:N259*Raw_Data!M5:M259)-SUM(Raw_Data!P5:P259) -> 13165.04 | E45: Revenue foregone due to discount strategy
...
